Workbook

Sheet Notes
A1: Date | B1: 46098
A2: Version | B2: 1
A3: Created by | B3: Erik Tuononen
A4: Reviewer | B4: Kevin Nebiolo
A6: How to use:
A7: 1) Set confidence level in Inputs!B2 (default 0.95).
A8: 2) Enter Qcap in Inputs column A.
A9: 3) All other parameters (D2, ratio, D1, N, B, RPM, Qopt) compute automatically. | I9: Description:
I10: We’ve completed an Excel‑based prediction tool for estimating key Francis turbine parameters using Qcap (individual turbine hydraulic capacity in m³/s) as the only user‑supplied input. The tool derives its estimates of D2, D1, B, RPM, Qopt, and N (number of blades) from linear relationships identified in our compiled dataset of Francis turbine specifications. Each relationship is modeled using a simple linear regression of the form y = b₀ + b₁x, where b₀ (intercept) and b₁ (slope) were calculated with regression methods (e.g., relationships such as Qcap ~ Qopt, D2 ~ Qcap, RPM ~ Qcap). These regression equations, together with Excel‑based formulas for upper and lower confidence bounds, form the basis of the tool. Confidence intervals are user‑adjustable and computed using CI_low = ŷ – t * SE_mean and CI_high = ŷ + t * SE_mean​, where the t-value depends on the chosen confidence level and the regression's degrees of freedom. You will have to carry out a sensitivity analysis using the FEIRA tool where you run seperate simulations using the upper and lower values from CI.

Sheet Inputs
A1: Parameter | B1: Value
A2: Confidence level (0-1) | B2: 0.95
A4: Notes | B4: Enter Qcap below; all other values auto-computed.
A5: Qcap

Sheet Models
A3: Model: D2 ~ Qcap
A4: b0 | B4: 0.73061575
A5: b1 | B5: 0.050447643
A6: sigma | B6: 0.58258988
A7: n | B7: 44
A8: xbar | B8: 27.415112
A9: Sxx | B9: 17098.407
A10: df | B10: 42
A12: Auto: Qcap -> D2 -> ratio -> D1
A13: b0 | B13: 0.8575001
A14: b1 | B14: -0.046399789
A15: sigma | B15: 0.17850317
A16: n | B16: 44
A17: xbar | B17: 2.1136435
A18: Sxx | B18: 57.770102
A19: df | B19: 42
A21: Model: N ~ D1/D2
A22: b0 | B22: 10.019191
A23: b1 | B23: 4.7630251
A24: sigma | B24: 3.4330322
A25: n | B25: 44
A26: xbar | B26: 0.75942749
A27: Sxx | B27: 1.4626376
A28: df | B28: 42
A30: Model: B ~ Qcap
A31: b0 | B31: 0.34572373
A32: b1 | B32: 0.011294201
A33: sigma | B33: 0.22737182
A34: n | B34: 44
A35: xbar | B35: 27.415112
A36: Sxx | B36: 17098.407
A37: df | B37: 42
A39: Model: RPM ~ Qcap
A40: b0 | B40: 265.44128
A41: b1 | B41: -2.2292716
A42: sigma | B42: 68.37221
A43: n | B43: 49
A44: xbar | B44: 27.969441
A45: Sxx | B45: 20752.605
A46: df | B46: 47
...

Sheet Results
A2: D2 from Qcap (Model: D2 ~ Qcap)
A3: X | B3: Y_hat | C3: CI_low | D3: CI_high | E3: Y_hat = D2
A4: =Inputs!$A$6 -> 0 | B4: =Models!$B$4 + Models!$B$5*Inputs!$A$6 -> 0.73061575 | C4: =(Models!$B$4 + Models!$B$5*Inputs!$A$6) - _xlfn.T.INV.2T(1-Inputs!$B$2,Models!$B$10)*Models!$B$6*SQRT(1/Models!$B$7 + (Inputs!$A$6-Models!$B$8)^2/Models!$B$9) -> 0.42700846 | D4: =(Models!$B$4 + Models!$B$5*Inputs!$A$6) + _xlfn.T.INV.2T(1-Inputs!$B$2,Models!$B$10)*Models!$B$6*SQRT(1/Models!$B$7 + (Inputs!$A$6-Models!$B$8)^2/Models!$B$9) -> 1.034223
A6: B from Qcap (Model: B ~ Qcap)
A7: X | B7: Y_hat | C7: CI_low | D7: CI_high | E7: Y_hat=B
A8: =Inputs!$A$6 -> 0 | B8: =Models!$B$31 + Models!$B$32*Inputs!$A$6 -> 0.34572373 | C8: =(Models!$B$31 + Models!$B$32*Inputs!$A$6) - _xlfn.T.INV.2T(1-Inputs!$B$2,Models!$B$37)*Models!$B$33*SQRT(1/Models!$B$34 + (Inputs!$A$6-Models!$B$35)^2/Models!$B$36) -> 0.22723259 | D8: =(Models!$B$31 + Models!$B$32*Inputs!$A$6) + _xlfn.T.INV.2T(1-Inputs!$B$2,Models!$B$37)*Models!$B$33*SQRT(1/Models!$B$34 + (Inputs!$A$6-Models!$B$35)^2/Models!$B$36) -> 0.46421488
A10: RPM from Qcap (Model: RPM ~ Qcap)
A11: X | B11: Y_hat | C11: CI_low | D11: CI_high | E11: Y_hat=RPM
A12: =Inputs!$A$6 -> 0 | B12: =Models!$B$40 + Models!$B$41*Inputs!$A$6 -> 265.44128 | C12: =(Models!$B$40 + Models!$B$41*Inputs!$A$6) - _xlfn.T.INV.2T(1-Inputs!$B$2,Models!$B$46)*Models!$B$42*SQRT(1/Models!$B$43 + (Inputs!$A$6-Models!$B$44)^2/Models!$B$45) -> 232.28581 | D12: =(Models!$B$40 + Models!$B$41*Inputs!$A$6) + _xlfn.T.INV.2T(1-Inputs!$B$2,Models!$B$46)*Models!$B$42*SQRT(1/Models!$B$43 + (Inputs!$A$6-Models!$B$44)^2/Models!$B$45) -> 298.59674
A14: Qopt from Qcap (Model: Qopt ~ Qcap)
A15: X | B15: Y_hat | C15: CI_low | D15: CI_high | E15: Y_hat=Qopt
A16: =Inputs!$A$6 -> 0 | B16: =Models!$B$49 + Models!$B$50*Inputs!$A$6 -> -1.3780858 | C16: =(Models!$B$49 + Models!$B$50*Inputs!$A$6) - _xlfn.T.INV.2T(1-Inputs!$B$2,Models!$B$55)*Models!$B$51*SQRT(1/Models!$B$52 + (Inputs!$A$6-Models!$B$53)^2/Models!$B$54) -> -2.2929473 | D16: =(Models!$B$49 + Models!$B$50*Inputs!$A$6) + _xlfn.T.INV.2T(1-Inputs!$B$2,Models!$B$55)*Models!$B$51*SQRT(1/Models!$B$52 + (Inputs!$A$6-Models!$B$53)^2/Models!$B$54) -> -0.46322441
A18: D1 & Ratio from D2 (Auto: Qcap -> D2 -> ratio -> D1)
A19: D2_input | B19: ratio_hat | C19: D1_hat | D19: CI_low | E19: CI_high | F19: D1_hat=D1
A20: =Results!$B$4 -> 0.73061575 | B20: =Models!$B$13 + Models!$B$14*Results!$B$4 -> 0.82359968 | C20: =(Models!$B$13 + Models!$B$14*Results!$B$4)*Results!$B$4 -> 0.6017349 | D20: =(Models!$B$13 + Models!$B$14*Results!$B$4) - _xlfn.T.INV.2T(1-Inputs!$B$2,Models!$B$19)*Models!$B$15*SQRT(1/Models!$B$16 + (Results!$B$4-Models!$B$17)^2/Models!$B$18) -> 0.73847674 | E20: =(Models!$B$13 + Models!$B$14*Results!$B$4) + _xlfn.T.INV.2T(1-Inputs!$B$2,Models!$B$19)*Models!$B$15*SQRT(1/Models!$B$16 + (Results!$B$4-Models!$B$17)^2/Models!$B$18) -> 0.90872263
A22: N from ratio (Model: N ~ D1/D2)
A23: ratio_input | B23: N_hat | C23: CI_low | D23: CI_high | E23: N_hat=N
A24: =Results!$B$20 -> 0.82359968 | B24: =Models!$B$22 + Models!$B$23*Results!$B$20 -> 13.942017 | C24: =(Models!$B$22 + Models!$B$23*Results!$B$20) - _xlfn.T.INV.2T(1-Inputs!$B$2,Models!$B$28)*Models!$B$24*SQRT(1/Models!$B$25 + (Results!$B$20-Models!$B$26)^2/Models!$B$27) -> 12.834755 | D24: =(Models!$B$22 + Models!$B$23*Results!$B$20) + _xlfn.T.INV.2T(1-Inputs!$B$2,Models!$B$28)*Models!$B$24*SQRT(1/Models!$B$25 + (Results!$B$20-Models!$B$26)^2/Models!$B$27) -> 15.04928
